<inh f='include/c++/10/bits/exception.h' l='60' c='std::exception'/>
<def f='qv2ray/test/catch.hpp' l='3917' ll='3926'/>
<use f='qv2ray/test/catch.hpp' l='4168' c='_ZN5Catch10Generators15FilterGeneratorC1EOTL0__ONS0_16GeneratorWrapperIT_EE'/>
<use f='qv2ray/test/catch.hpp' l='4304' c='_ZN5Catch10Generators14ChunkGeneratorC1EmNS0_16GeneratorWrapperIT_EE'/>
<use f='qv2ray/test/catch.hpp' l='4716' c='_ZN5Catch10Generators17IteratorGeneratorC1ETL0__TL0_0_'/>
<size>16</size>
<mbr r='Catch::GeneratorException::m_msg' o='64' t='const char *const'/>
<fun r='_ZN5Catch18GeneratorExceptionC1EPKc'/>
<fun r='_ZNK5Catch18GeneratorException4whatEv'/>
<fun r='_ZNK5Catch18GeneratorException4whatEv'/>
